Workbook

Sheet Raw Data
A1: OrderID | B1: Date | C1: CustomerID | D1: Product | E1: Quantity | F1: UnitPrice | G1: ShippingAddress | H1: PaymentMethod | I1: OrderStatus | J1: TrackingNumber | K1: ItemsInCart | L1: CouponCode | M1: ReferralSource | N1: TotalPrice
A2: ORD200000 | B2: 44930 | C2: C72649 | D2: Monitor | E2: 5 | F2: 570.62 | G2: 928 Main St | H2: Debit Card | I2: Shipped | J2: TRK37947903 | K2: 7 | L2: SAVE10 | M2: Instagram | N2: 2853.1
A3: ORD200001 | B3: 45527 | C3: C75739 | D3: Phone | E3: 2 | F3: 151.35 | G3: 823 Main St | H3: Online | I3: Shipped | J3: TRK91186779 | K3: 3 | L3: SAVE10 | M3: Referral | N3: 302.7
A4: ORD200002 | B4: 45349 | C4: C81728 | D4: Tablet | E4: 5 | F4: 550.68 | G4: 512 Main St | H4: Credit Card | I4: Cancelled | J4: TRK42903982 | K4: 8 | L4: FREESHIP | M4: Email | N4: 2753.4
A5: ORD200003 | B5: 45214 | C5: C33540 | D5: Chair | E5: 1 | F5: 273.19 | G5: 275 Main St | H5: Debit Card | I5: Returned | J5: TRK62788070 | K5: 5 | L5: SAVE10 | M5: Facebook | N5: 273.19
A6: ORD200004 | B6: 45785 | C6: C81840 | D6: Printer | E6: 4 | F6: 626.01 | G6: 668 Main St | H6: Online | I6: Delivered | J6: TRK29241424 | K6: 8 | L6: SAVE10 | M6: Email | N6: 2504.04
A7: ORD200005 | B7: 45222 | C7: C37249 | D7: Phone | E7: 2 | F7: 245.86 | G7: 934 Main St | H7: Credit Card | I7: Shipped | J7: TRK72976927 | K7: 4 | L7: SAVE10 | M7: Instagram | N7: 491.72
A8: ORD200006 | B8: 45825 | C8: C83492 | D8: Laptop | E8: 1 | F8: 664.42 | G8: 986 Main St | H8: Gift Card | I8: Returned | J8: TRK96417362 | K8: 6 | L8: SAVE10 | M8: Facebook | N8: 664.42
A9: ORD200007 | B9: 45058 | C9: C41460 | D9: Monitor | E9: 5 | F9: 149.55 | G9: 706 Main St | H9: Cash | I9: Shipped | J9: TRK78809193 | K9: 9 | L9: FREESHIP | M9: Facebook | N9: 747.75
A10: ORD200008 | B10: 45749 | C10: C26817 | D10: Phone | E10: 2 | F10: 134.28 | G10: 904 Main St | H10: Gift Card | I10: Cancelled | J10: TRK61042692 | K10: 2 | M10: Email | N10: 268.56
A11: ORD200009 | B11: 45251 | C11: C31946 | D11: Desk | E11: 4 | F11: 509.38 | G11: 102 Main St | H11: Credit Card | I11: Shipped | J11: TRK33478363 | K11: 6 | L11: SAVE10 | M11: Google | N11: 2037.52
A12: ORD200010 | B12: 45289 | C12: C43443 | D12: Tablet | E12: 5 | F12: 625.97 | G12: 333 Main St | H12: Credit Card | I12: Returned | J12: TRK98859248 | K12: 9 | L12: WINTER15 | M12: Instagram | N12: 3129.85
A13: ORD200011 | B13: 45339 | C13: C93861 | D13: Monitor | E13: 3 | F13: 49.14 | G13: 831 Main St | H13: Online | I13: Returned | J13: TRK48234646 | K13: 7 | L13: SAVE10 | M13: Email | N13: 147.42
A14: ORD200012 | B14: 45580 | C14: C38785 | D14: Monitor | E14: 2 | F14: 180.5 | G14: 179 Main St | H14: Debit Card | I14: Pending | J14: TRK20419991 | K14: 6 | L14: FREESHIP | M14: Referral | N14: 361
A15: ORD200013 | B15: 45168 | C15: C88348 | D15: Laptop | E15: 3 | F15: 201.49 | G15: 903 Main St | H15: Credit Card | I15: Returned | J15: TRK81913874 | K15: 4 | L15: FREESHIP | M15: Facebook | N15: 604.47
A16: ORD200014 | B16: 45012 | C16: C98474 | D16: Tablet | E16: 2 | F16: 393.33 | G16: 980 Main St | H16: Debit Card | I16: Pending | J16: TRK79186539 | K16: 3 | L16: SAVE10 | M16: Instagram | N16: 786.66
A17: ORD200015 | B17: 45124 | C17: C39416 | D17: Printer | E17: 1 | F17: 473.96 | G17: 942 Main St | H17: Cash | I17: Delivered | J17: TRK54930938 | K17: 3 | M17: Google | N17: 473.96
A18: ORD200016 | B18: 44950 | C18: C28976 | D18: Printer | E18: 2 | F18: 533.81 | G18: 914 Main St | H18: Credit Card | I18: Pending | J18: TRK13194259 | K18: 3 | L18: FREESHIP | M18: Email | N18: 1067.62
A19: ORD200017 | B19: 45353 | C19: C60672 | D19: Tablet | E19: 1 | F19: 423.4 | G19: 382 Main St | H19: Debit Card | I19: Shipped | J19: TRK11972116 | K19: 3 | M19: Referral | N19: 423.4
A20: ORD200018 | B20: 45742 | C20: C84329 | D20: Desk | E20: 1 | F20: 431.44 | G20: 891 Main St | H20: Gift Card | I20: Pending | J20: TRK65191045 | K20: 3 | L20: SAVE10 | M20: Facebook | N20: 431.44
A21: ORD200019 | B21: 44949 | C21: C14552 | D21: Monitor | E21: 5 | F21: 224 | G21: 273 Main St | H21: Cash | I21: Returned | J21: TRK59101365 | K21: 9 | L21: SAVE10 | M21: Google | N21: 1120
A22: ORD200020 | B22: 45054 | C22: C54829 | D22: Chair | E22: 5 | F22: 62.51 | G22: 587 Main St | H22: Cash | I22: Pending | J22: TRK16718651 | K22: 9 | L22: WINTER15 | M22: Instagram | N22: 312.55
A23: ORD200021 | B23: 45613 | C23: C99023 | D23: Monitor | E23: 4 | F23: 342.95 | G23: 569 Main St | H23: Cash | I23: Delivered | J23: TRK52646983 | K23: 6 | M23: Google | N23: 1371.8
A24: ORD200022 | B24: 44955 | C24: C34416 | D24: Monitor | E24: 2 | F24: 49.62 | G24: 633 Main St | H24: Online | I24: Pending | J24: TRK75937350 | K24: 2 | L24: SAVE10 | M24: Google | N24: 99.24
A25: ORD200023 | B25: 45756 | C25: C42372 | D25: Phone | E25: 4 | F25: 273.25 | G25: 755 Main St | H25: Debit Card | I25: Cancelled | J25: TRK36168083 | K25: 5 | L25: FREESHIP | M25: Referral | N25: 1093
A26: ORD200024 | B26: 45595 | C26: C17470 | D26: Laptop | E26: 2 | F26: 230.95 | G26: 956 Main St | H26: Online | I26: Delivered | J26: TRK28775057 | K26: 3 | L26: WINTER15 | M26: Referral | N26: 461.9
A27: ORD200025 | B27: 45497 | C27: C42577 | D27: Monitor | E27: 1 | F27: 399.98 | G27: 709 Main St | H27: Debit Card | I27: Delivered | J27: TRK69423327 | K27: 3 | L27: WINTER15 | M27: Email | N27: 399.98
A28: ORD200026 | B28: 45357 | C28: C21944 | D28: Laptop | E28: 5 | F28: 59.55 | G28: 296 Main St | H28: Online | I28: Delivered | J28: TRK80276812 | K28: 6 | M28: Referral | N28: 297.75
A29: ORD200027 | B29: 45344 | C29: C97593 | D29: Printer | E29: 1 | F29: 472.74 | G29: 881 Main St | H29: Online | I29: Shipped | J29: TRK89117573 | K29: 6 | L29: WINTER15 | M29: Google | N29: 472.74
A30: ORD200028 | B30: 45251 | C30: C59823 | D30: Phone | E30: 4 | F30: 160.07 | G30: 568 Main St | H30: Online | I30: Pending | J30: TRK65895539 | K30: 5 | M30: Email | N30: 640.28
A31: ORD200029 | B31: 45555 | C31: C33260 | D31: Desk | E31: 3 | F31: 423.53 | G31: 930 Main St | H31: Credit Card | I31: Delivered | J31: TRK59744090 | K31: 6 | L31: SAVE10 | M31: Referral | N31: 1270.59
A32: ORD200030 | B32: 45738 | C32: C44267 | D32: Monitor | E32: 2 | F32: 426.7 | G32: 895 Main St | H32: Online | I32: Pending | J32: TRK54751444 | K32: 5 | L32: SAVE10 | M32: Referral | N32: 853.4
A33: ORD200031 | B33: 45107 | C33: C26445 | D33: Chair | E33: 3 | F33: 500.08 | G33: 996 Main St | H33: Debit Card | I33: Returned | J33: TRK31229981 | K33: 6 | M33: Facebook | N33: 1500.24
A34: ORD200032 | B34: 45047 | C34: C12388 | D34: Tablet | E34: 5 | F34: 536.72 | G34: 830 Main St | H34: Cash | I34: Delivered | J34: TRK99261395 | K34: 10 | M34: Email | N34: 2683.6
A35: ORD200033 | B35: 45082 | C35: C52184 | D35: Chair | E35: 1 | F35: 162.77 | G35: 912 Main St | H35: Online | I35: Cancelled | J35: TRK73312471 | K35: 4 | L35: WINTER15 | M35: Facebook | N35: 162.77
A36: ORD200034 | B36: 44933 | C36: C67195 | D36: Chair | E36: 4 | F36: 576.52 | G36: 926 Main St | H36: Credit Card | I36: Pending | J36: TRK55467915 | K36: 5 | L36: WINTER15 | M36: Facebook | N36: 2306.08
A37: ORD200035 | B37: 45633 | C37: C50304 | D37: Monitor | E37: 2 | F37: 465.15 | G37: 128 Main St | H37: Online | I37: Shipped | J37: TRK46850888 | K37: 2 | L37: SAVE10 | M37: Facebook | N37: 930.3
A38: ORD200036 | B38: 45785 | C38: C59337 | D38: Laptop | E38: 2 | F38: 534.43 | G38: 465 Main St | H38: Debit Card | I38: Pending | J38: TRK50961250 | K38: 5 | M38: Facebook | N38: 1068.86
A39: ORD200037 | B39: 45579 | C39: C10054 | D39: Laptop | E39: 2 | F39: 76.74 | G39: 409 Main St | H39: Cash | I39: Returned | J39: TRK94005261 | K39: 7 | L39: SAVE10 | M39: Instagram | N39: 153.48
A40: ORD200038 | B40: 45645 | C40: C15924 | D40: Laptop | E40: 1 | F40: 245.89 | G40: 549 Main St | H40: Debit Card | I40: Delivered | J40: TRK14835975 | K40: 3 | L40: SAVE10 | M40: Google | N40: 245.89
...

Sheet Cleaned Data
A1: OrderID | B1: Date | C1: CustomerID | D1: Product | E1: Quantity | F1: UnitPrice | G1: ShippingAddress | H1: PaymentMethod | I1: OrderStatus | J1: TrackingNumber | K1: ItemsInCart | L1: CouponCode | M1: ReferralSource | N1: TotalPrice
A2: ='Raw Data'!A2 -> ORD200000 | B2: ='Raw Data'!B2 -> 44930 | C2: ='Raw Data'!C2 -> C72649 | D2: ='Raw Data'!D2 -> Monitor | E2: ='Raw Data'!E2 -> 5 | F2: ='Raw Data'!F2 -> 570.62 | G2: ='Raw Data'!G2 -> 928 Main St | H2: ='Raw Data'!H2 -> Debit Card | ... K2: ='Raw Data'!K2 -> 7 | L2: =IF('Raw Data'!L2="","No Coupon",'Raw Data'!L2) -> SAVE10 | M2: ='Raw Data'!M2 -> Instagram | N2: ='Raw Data'!N2 -> 2853.1
A3: ='Raw Data'!A3 -> ORD200001 | B3: ='Raw Data'!B3 -> 45527 | C3: ='Raw Data'!C3 -> C75739 | D3: ='Raw Data'!D3 -> Phone | E3: ='Raw Data'!E3 -> 2 | F3: ='Raw Data'!F3 -> 151.35 | G3: ='Raw Data'!G3 -> 823 Main St | H3: ='Raw Data'!H3 -> Online | ... K3: ='Raw Data'!K3 -> 3 | L3: =IF('Raw Data'!L3="","No Coupon",'Raw Data'!L3) -> SAVE10 | M3: ='Raw Data'!M3 -> Referral | N3: ='Raw Data'!N3 -> 302.7
A4: ='Raw Data'!A4 -> ORD200002 | B4: ='Raw Data'!B4 -> 45349 | C4: ='Raw Data'!C4 -> C81728 | D4: ='Raw Data'!D4 -> Tablet | E4: ='Raw Data'!E4 -> 5 | F4: ='Raw Data'!F4 -> 550.68 | G4: ='Raw Data'!G4 -> 512 Main St | H4: ='Raw Data'!H4 -> Credit Card | ... K4: ='Raw Data'!K4 -> 8 | L4: =IF('Raw Data'!L4="","No Coupon",'Raw Data'!L4) -> FREESHIP | M4: ='Raw Data'!M4 -> Email | N4: ='Raw Data'!N4 -> 2753.4
A5: ='Raw Data'!A5 -> ORD200003 | B5: ='Raw Data'!B5 -> 45214 | C5: ='Raw Data'!C5 -> C33540 | D5: ='Raw Data'!D5 -> Chair | E5: ='Raw Data'!E5 -> 1 | F5: ='Raw Data'!F5 -> 273.19 | G5: ='Raw Data'!G5 -> 275 Main St | H5: ='Raw Data'!H5 -> Debit Card | ... K5: ='Raw Data'!K5 -> 5 | L5: =IF('Raw Data'!L5="","No Coupon",'Raw Data'!L5) -> SAVE10 | M5: ='Raw Data'!M5 -> Facebook | N5: ='Raw Data'!N5 -> 273.19
A6: ='Raw Data'!A6 -> ORD200004 | B6: ='Raw Data'!B6 -> 45785 | C6: ='Raw Data'!C6 -> C81840 | D6: ='Raw Data'!D6 -> Printer | E6: ='Raw Data'!E6 -> 4 | F6: ='Raw Data'!F6 -> 626.01 | G6: ='Raw Data'!G6 -> 668 Main St | H6: ='Raw Data'!H6 -> Online | ... K6: ='Raw Data'!K6 -> 8 | L6: =IF('Raw Data'!L6="","No Coupon",'Raw Data'!L6) -> SAVE10 | M6: ='Raw Data'!M6 -> Email | N6: ='Raw Data'!N6 -> 2504.04
A7: ='Raw Data'!A7 -> ORD200005 | B7: ='Raw Data'!B7 -> 45222 | C7: ='Raw Data'!C7 -> C37249 | D7: ='Raw Data'!D7 -> Phone | E7: ='Raw Data'!E7 -> 2 | F7: ='Raw Data'!F7 -> 245.86 | G7: ='Raw Data'!G7 -> 934 Main St | H7: ='Raw Data'!H7 -> Credit Card | ... K7: ='Raw Data'!K7 -> 4 | L7: =IF('Raw Data'!L7="","No Coupon",'Raw Data'!L7) -> SAVE10 | M7: ='Raw Data'!M7 -> Instagram | N7: ='Raw Data'!N7 -> 491.72
A8: ='Raw Data'!A8 -> ORD200006 | B8: ='Raw Data'!B8 -> 45825 | C8: ='Raw Data'!C8 -> C83492 | D8: ='Raw Data'!D8 -> Laptop | E8: ='Raw Data'!E8 -> 1 | F8: ='Raw Data'!F8 -> 664.42 | G8: ='Raw Data'!G8 -> 986 Main St | H8: ='Raw Data'!H8 -> Gift Card | ... K8: ='Raw Data'!K8 -> 6 | L8: =IF('Raw Data'!L8="","No Coupon",'Raw Data'!L8) -> SAVE10 | M8: ='Raw Data'!M8 -> Facebook | N8: ='Raw Data'!N8 -> 664.42
A9: ='Raw Data'!A9 -> ORD200007 | B9: ='Raw Data'!B9 -> 45058 | C9: ='Raw Data'!C9 -> C41460 | D9: ='Raw Data'!D9 -> Monitor | E9: ='Raw Data'!E9 -> 5 | F9: ='Raw Data'!F9 -> 149.55 | G9: ='Raw Data'!G9 -> 706 Main St | H9: ='Raw Data'!H9 -> Cash | ... K9: ='Raw Data'!K9 -> 9 | L9: =IF('Raw Data'!L9="","No Coupon",'Raw Data'!L9) -> FREESHIP | M9: ='Raw Data'!M9 -> Facebook | N9: ='Raw Data'!N9 -> 747.75
A10: ='Raw Data'!A10 -> ORD200008 | B10: ='Raw Data'!B10 -> 45749 | C10: ='Raw Data'!C10 -> C26817 | D10: ='Raw Data'!D10 -> Phone | E10: ='Raw Data'!E10 -> 2 | F10: ='Raw Data'!F10 -> 134.28 | G10: ='Raw Data'!G10 -> 904 Main St | H10: ='Raw Data'!H10 -> Gift Card | ... K10: ='Raw Data'!K10 -> 2 | L10: =IF('Raw Data'!L10="","No Coupon",'Raw Data'!L10) -> No Coupon | M10: ='Raw Data'!M10 -> Email | N10: ='Raw Data'!N10 -> 268.56
A11: ='Raw Data'!A11 -> ORD200009 | B11: ='Raw Data'!B11 -> 45251 | C11: ='Raw Data'!C11 -> C31946 | D11: ='Raw Data'!D11 -> Desk | E11: ='Raw Data'!E11 -> 4 | F11: ='Raw Data'!F11 -> 509.38 | G11: ='Raw Data'!G11 -> 102 Main St | H11: ='Raw Data'!H11 -> Credit Card | ... K11: ='Raw Data'!K11 -> 6 | L11: =IF('Raw Data'!L11="","No Coupon",'Raw Data'!L11) -> SAVE10 | M11: ='Raw Data'!M11 -> Google | N11: ='Raw Data'!N11 -> 2037.52
A12: ='Raw Data'!A12 -> ORD200010 | B12: ='Raw Data'!B12 -> 45289 | C12: ='Raw Data'!C12 -> C43443 | D12: ='Raw Data'!D12 -> Tablet | E12: ='Raw Data'!E12 -> 5 | F12: ='Raw Data'!F12 -> 625.97 | G12: ='Raw Data'!G12 -> 333 Main St | H12: ='Raw Data'!H12 -> Credit Card | ... K12: ='Raw Data'!K12 -> 9 | L12: =IF('Raw Data'!L12="","No Coupon",'Raw Data'!L12) -> WINTER15 | M12: ='Raw Data'!M12 -> Instagram | N12: ='Raw Data'!N12 -> 3129.85
A13: ='Raw Data'!A13 -> ORD200011 | B13: ='Raw Data'!B13 -> 45339 | C13: ='Raw Data'!C13 -> C93861 | D13: ='Raw Data'!D13 -> Monitor | E13: ='Raw Data'!E13 -> 3 | F13: ='Raw Data'!F13 -> 49.14 | G13: ='Raw Data'!G13 -> 831 Main St | H13: ='Raw Data'!H13 -> Online | ... K13: ='Raw Data'!K13 -> 7 | L13: =IF('Raw Data'!L13="","No Coupon",'Raw Data'!L13) -> SAVE10 | M13: ='Raw Data'!M13 -> Email | N13: ='Raw Data'!N13 -> 147.42
... A1201: ='Raw Data'!A1201 -> ORD201199 | B1201: ='Raw Data'!B1201 -> 45088 | C1201: ='Raw Data'!C1201 -> C57502 | D1201: ='Raw Data'!D1201 -> Tablet | E1201: ='Raw Data'!E1201 -> 4 | F1201: ='Raw Data'!F1201 -> 560.58 | G1201: ='Raw Data'!G1201 -> 201 Main St | H1201: ='Raw Data'!H1201 -> Gift Card | ... K1201: ='Raw Data'!K1201 -> 6 | L1201: =IF('Raw Data'!L1201="","No Coupon",'Raw Data'!L1201) -> SAVE10 | M1201: ='Raw Data'!M1201 -> Referral | N1201: ='Raw Data'!N1201 -> 2242.32

Sheet QA Validation
A1: Data Quality Validation Report
A2: DecodeLabs | Project 1: Data Cleaning & Preparation
A4: 1. Unique Identifier Check (OrderID)
A5: Metric | B5: Result
A6: Total Rows | B6: =COUNTA('Raw Data'!A2:A1201) -> 1200
A7: Unique OrderIDs | B7: =SUMPRODUCT(1/COUNTIF('Raw Data'!A2:A1201,'Raw Data'!A2:A1201)) -> 1200
A8: Duplicate Count | B8: =B6-B7 -> 0
A9: Duplicate Error Rate | B9: =B8/B6 -> 0
A10: Status | B10: =IF(B8=0,"PASS - 0% Duplicates","FAIL - Duplicates Found") -> PASS - 0% Duplicates
A12: 2. Unique Identifier Check (TrackingNumber)
A13: Metric | B13: Result
A14: Unique TrackingNumbers | B14: =SUMPRODUCT(1/COUNTIF('Raw Data'!J2:J1201,'Raw Data'!J2:J1201)) -> 1200
A15: Duplicate Count | B15: =COUNTA('Raw Data'!J2:J1201)-B14 -> 0
A16: Status | B16: =IF(B15=0,"PASS - 0% Duplicates","FAIL - Duplicates Found") -> PASS - 0% Duplicates
A18: 3. Date Format Validation
A19: Metric | B19: Result
A20: Total Date Entries | B20: =COUNTA('Raw Data'!B2:B1201) -> 1200
A21: Valid Date Values | B21: =SUMPRODUCT(--ISNUMBER('Raw Data'!B2:B1201*1)) -> 1200
A22: Invalid/Text Dates | B22: =B20-B21 -> 0
A23: Dates Outside Expected Range (2023-2025) | B23: =SUMPRODUCT(--(('Raw Data'!B2:B1201<DATE(2023,1,1))+('Raw Data'!B2:B1201>DATE(2025,12,31)))) -> 0
A24: Status | B24: =IF(AND(B22=0,B23=0),"PASS - 0% Format Errors","FAIL - Format Issues Found") -> PASS - 0% Format Errors
A26: 4. Missing Value Audit (All Columns)
A27: Column | B27: Missing Count | C27: Missing %
A28: OrderID | B28: =COUNTBLANK('Raw Data'!A2:A1201) -> 0 | C28: =B28/1200 -> 0
A29: Date | B29: =COUNTBLANK('Raw Data'!B2:B1201) -> 0 | C29: =B29/1200 -> 0
A30: CustomerID | B30: =COUNTBLANK('Raw Data'!C2:C1201) -> 0 | C30: =B30/1200 -> 0
A31: Product | B31: =COUNTBLANK('Raw Data'!D2:D1201) -> 0 | C31: =B31/1200 -> 0
A32: Quantity | B32: =COUNTBLANK('Raw Data'!E2:E1201) -> 0 | C32: =B32/1200 -> 0
A33: UnitPrice | B33: =COUNTBLANK('Raw Data'!F2:F1201) -> 0 | C33: =B33/1200 -> 0
A34: ShippingAddress | B34: =COUNTBLANK('Raw Data'!G2:G1201) -> 0 | C34: =B34/1200 -> 0
A35: PaymentMethod | B35: =COUNTBLANK('Raw Data'!H2:H1201) -> 0 | C35: =B35/1200 -> 0
A36: OrderStatus | B36: =COUNTBLANK('Raw Data'!I2:I1201) -> 0 | C36: =B36/1200 -> 0
A37: TrackingNumber | B37: =COUNTBLANK('Raw Data'!J2:J1201) -> 0 | C37: =B37/1200 -> 0
A38: ItemsInCart | B38: =COUNTBLANK('Raw Data'!K2:K1201) -> 0 | C38: =B38/1200 -> 0
A39: CouponCode | B39: =COUNTBLANK('Raw Data'!L2:L1201) -> 309 | C39: =B39/1200 -> 0.2575
A40: ReferralSource | B40: =COUNTBLANK('Raw Data'!M2:M1201) -> 0 | C40: =B40/1200 -> 0
A41: TotalPrice | B41: =COUNTBLANK('Raw Data'!N2:N1201) -> 0 | C41: =B41/1200 -> 0
A43: Note: CouponCode is the only column with missing values (309 blanks, 25.8%). This is a valid business state, not a data error, it represents orders placed without a coupon. In the Cleaned Data sheet, these blanks are labeled 'No Coupon' for clarity rather than left blank.
A45: Overall Project Scorecard
A46: ✔ Unique Identifiers: 0% duplicate error rate (OrderID and TrackingNumber both fully unique) ✔ Date Formats: 0% format error rate (all 1,200 dates valid and within expected range) ✔ Missing Values: identified and handled (CouponCode blanks labeled "No Coupon")
